<?xml version="1.0" encoding="utf-8"?>
<!-- This URDF was automatically created by SolidWorks to URDF Exporter! Originally created by Stephen Brawner (brawner@gmail.com) 
     Commit Version: 1.6.0-4-g7f85cfe  Build Version: 1.6.7995.38578
     For more information, please see http://wiki.ros.org/sw_urdf_exporter -->
<robot
  name="TestModule">
  <link
    name="base_link">
    <inertial>
      <origin
        xyz="-6.76297808727133E-09 0.0270550012386077 -2.75401897972608E-05"
        rpy="0 0 0" />
      <mass
        value="0.0495277420594313" />
      <inertia
        ixx="1.41497431902948E-05"
        ixy="-5.54976013985446E-13"
        ixz="3.69455240011523E-12"
        iyy="9.94040203055118E-06"
        iyz="-1.82886992505458E-07"
        izz="1.24597264635174E-05" />
    </inertial>
    <visual>
      <origin
        xyz="0 0 0"
        rpy="0 0 0" />
      <geometry>
        <mesh
          filename="package://TestModule/meshes/base_link.STL" />
      </geometry>
      <material
        name="">
        <color
          rgba="0.792156862745098 0.819607843137255 0.933333333333333 1" />
      </material>
    </visual>
    <collision>
      <origin
        xyz="0 0 0"
        rpy="0 0 0" />
      <geometry>
        <mesh
          filename="package://TestModule/meshes/base_link.STL" />
      </geometry>
    </collision>
  </link>
  <link
    name="head">
    <inertial>
      <origin
        xyz="0.000524437183906545 -0.0129585093549575 0.000453299518954085"
        rpy="0 0 0" />
      <mass
        value="0.00301708508515438" />
      <inertia
        ixx="4.38014874293169E-07"
        ixy="4.25463023339811E-23"
        ixz="-1.06031804154792E-38"
        iyy="4.43521393164985E-07"
        iyz="9.48867566928348E-39"
        izz="4.38014874293169E-07" />
    </inertial>
    <visual>
      <origin
        xyz="0 0 0"
        rpy="0 0 0" />
      <geometry>
        <mesh
          filename="package://TestModule/meshes/head.STL" />
      </geometry>
      <material
        name="">
        <color
          rgba="0.792156862745098 0.819607843137255 0.933333333333333 1" />
      </material>
    </visual>
    <collision>
      <origin
        xyz="0 0 0"
        rpy="0 0 0" />
      <geometry>
        <mesh
          filename="package://TestModule/meshes/head.STL" />
      </geometry>
    </collision>
  </link>
  <joint
    name="base"
    type="fixed">
    <origin
      xyz="0 0 0"
      rpy="0 0 0" />
    <parent
      link="base_link" />
    <child
      link="head" />
    <axis
      xyz="0 0 0" />
  </joint>
  <link
    name="link1">
    <inertial>
      <origin
        xyz="0.0280266508378636 0.0506969680759189 -0.0215106904993164"
        rpy="0 0 0" />
      <mass
        value="0.065417433868186" />
      <inertia
        ixx="2.24094591970624E-05"
        ixy="-2.69240795685027E-06"
        ixz="-6.87230658368194E-09"
        iyy="1.94647754174922E-05"
        iyz="-1.24130496938715E-08"
        izz="2.25049138700149E-05" />
    </inertial>
    <visual>
      <origin
        xyz="0 0 0"
        rpy="0 0 0" />
      <geometry>
        <mesh
          filename="package://TestModule/meshes/link1.STL" />
      </geometry>
      <material
        name="">
        <color
          rgba="0.792156862745098 0.819607843137255 0.933333333333333 1" />
      </material>
    </visual>
    <collision>
      <origin
        xyz="0 0 0"
        rpy="0 0 0" />
      <geometry>
        <mesh
          filename="package://TestModule/meshes/link1.STL" />
      </geometry>
    </collision>
  </link>
  <joint
    name="J1"
    type="continuous">
    <origin
      xyz="0 0.04109 0.0236"
      rpy="0 0 0" />
    <parent
      link="base_link" />
    <child
      link="link1" />
    <axis
      xyz="0 0 1" />
  </joint>
  <link
    name="link2">
    <inertial>
      <origin
        xyz="0.0579265123384471 0.000441593607851336 0.0215545523773429"
        rpy="0 0 0" />
      <mass
        value="0.0654174298565387" />
      <inertia
        ixx="1.78768428854692E-05"
        ixy="-2.27096808257337E-07"
        ixz="1.6166196885044E-08"
        iyy="2.39976170754203E-05"
        iyz="1.97069207419383E-08"
        izz="2.25046857130434E-05" />
    </inertial>
    <visual>
      <origin
        xyz="0 0 0"
        rpy="0 0 0" />
      <geometry>
        <mesh
          filename="package://TestModule/meshes/link2.STL" />
      </geometry>
      <material
        name="">
        <color
          rgba="0.792156862745098 0.819607843137255 0.933333333333333 1" />
      </material>
    </visual>
    <collision>
      <origin
        xyz="0 0 0"
        rpy="0 0 0" />
      <geometry>
        <mesh
          filename="package://TestModule/meshes/link2.STL" />
      </geometry>
    </collision>
  </link>
  <joint
    name="J2"
    type="continuous">
    <origin
      xyz="0.023978 0.083408 -0.0215"
      rpy="1.5708 0 1.0654" />
    <parent
      link="link1" />
    <child
      link="link2" />
    <axis
      xyz="0 0 1" />
  </joint>
  <link
    name="link3">
    <inertial>
      <origin
        xyz="-0.0123754985795076 0.0565779592492555 0.0215106899619177"
        rpy="0 0 0" />
      <mass
        value="0.0654174369747681" />
      <inertia
        ixx="2.3642786403781E-05"
        ixy="1.44782811485755E-06"
        ixz="-3.04186225266057E-09"
        iyy="1.82314489672853E-05"
        iyz="1.3858657517201E-08"
        izz="2.25049146119028E-05" />
    </inertial>
    <visual>
      <origin
        xyz="0 0 0"
        rpy="0 0 0" />
      <geometry>
        <mesh
          filename="package://TestModule/meshes/link3.STL" />
      </geometry>
      <material
        name="">
        <color
          rgba="0.792156862745098 0.819607843137255 0.933333333333333 1" />
      </material>
    </visual>
    <collision>
      <origin
        xyz="0 0 0"
        rpy="0 0 0" />
      <geometry>
        <mesh
          filename="package://TestModule/meshes/link3.STL" />
      </geometry>
    </collision>
  </link>
  <joint
    name="J3"
    type="continuous">
    <origin
      xyz="0.084432 0.024267 0.021289"
      rpy="-1.5469 1.0653 -3.1134" />
    <parent
      link="link2" />
    <child
      link="link3" />
    <axis
      xyz="0 0 1" />
  </joint>
  <link
    name="link4">
    <inertial>
      <origin
        xyz="0.0556666217073585 0.0160295991461541 0.021306620681189"
        rpy="0 0 0" />
      <mass
        value="0.0654174306201065" />
      <inertia
        ixx="1.8453692391668E-05"
        ixy="-1.80334125556625E-06"
        ixz="2.91606716782043E-08"
        iyy="2.34251550734269E-05"
        iyz="-8.33540547367134E-08"
        izz="2.25002990395335E-05" />
    </inertial>
    <visual>
      <origin
        xyz="0 0 0"
        rpy="0 0 0" />
      <geometry>
        <mesh
          filename="package://TestModule/meshes/link4.STL" />
      </geometry>
      <material
        name="">
        <color
          rgba="0.792156862745098 0.819607843137255 0.933333333333333 1" />
      </material>
    </visual>
    <collision>
      <origin
        xyz="0 0 0"
        rpy="0 0 0" />
      <geometry>
        <mesh
          filename="package://TestModule/meshes/link4.STL" />
      </geometry>
    </collision>
  </link>
  <joint
    name="J4"
    type="continuous">
    <origin
      xyz="0.0008435 0.086772 0.0215"
      rpy="-1.5708 -0.063594 1.7866" />
    <parent
      link="link3" />
    <child
      link="link4" />
    <axis
      xyz="0 0 1" />
  </joint>
  <link
    name="link5">
    <inertial>
      <origin
        xyz="-0.0226920572684281 -0.0532986524485346 0.0215106903623613"
        rpy="0 0 0" />
      <mass
        value="0.0654174406564616" />
      <inertia
        ixx="2.31935756622329E-05"
        ixy="-2.07972462066008E-06"
        ixz="-5.54972786199524E-09"
        iyy="1.86806621367135E-05"
        iyz="-1.30581472153054E-08"
        izz="2.25049157288236E-05" />
    </inertial>
    <visual>
      <origin
        xyz="0 0 0"
        rpy="0 0 0" />
      <geometry>
        <mesh
          filename="package://TestModule/meshes/link5.STL" />
      </geometry>
      <material
        name="">
        <color
          rgba="0.792156862745098 0.819607843137255 0.933333333333333 1" />
      </material>
    </visual>
    <collision>
      <origin
        xyz="0 0 0"
        rpy="0 0 0" />
      <geometry>
        <mesh
          filename="package://TestModule/meshes/link5.STL" />
      </geometry>
    </collision>
  </link>
  <joint
    name="J5"
    type="continuous">
    <origin
      xyz="0.074667 0.046086 0.022465"
      rpy="1.8196 -1.3569 0.040747" />
    <parent
      link="link4" />
    <child
      link="link5" />
    <axis
      xyz="0 0 1" />
  </joint>
  <link
    name="link6">
    <inertial>
      <origin
        xyz="-0.0180491074912299 0.00437066108301949 0.021544034617132"
        rpy="0 0 0" />
      <mass
        value="0.0158896889808624" />
      <inertia
        ixx="8.13328192344153E-06"
        ixy="8.2510115231352E-07"
        ixz="-1.37905152531845E-08"
        iyy="1.13408230222265E-05"
        iyz="3.33942652627317E-09"
        izz="8.35517005485214E-06" />
    </inertial>
    <visual>
      <origin
        xyz="0 0 0"
        rpy="0 0 0" />
      <geometry>
        <mesh
          filename="package://TestModule/meshes/link6.STL" />
      </geometry>
      <material
        name="">
        <color
          rgba="0.792156862745098 0.819607843137255 0.933333333333333 1" />
      </material>
    </visual>
    <collision>
      <origin
        xyz="0 0 0"
        rpy="0 0 0" />
      <geometry>
        <mesh
          filename="package://TestModule/meshes/link6.STL" />
      </geometry>
    </collision>
  </link>
  <joint
    name="J6"
    type="continuous">
    <origin
      xyz="-0.050961 -0.070249 0.0215"
      rpy="1.5708 -0.02304 1.1686" />
    <parent
      link="link5" />
    <child
      link="link6" />
    <axis
      xyz="0 0 1" />
  </joint>
</robot>