<?xml version="1.0" encoding="utf-8"?>
<!-- This URDF was automatically created by SolidWorks to URDF Exporter! Originally created by Stephen Brawner (brawner@gmail.com) 
     Commit Version: 1.6.0-4-g7f85cfe  Build Version: 1.6.7995.38578
     For more information, please see http://wiki.ros.org/sw_urdf_exporter -->
<robot
  name="TestModule">
  <link
    name="base_link">
    <inertial>
      <origin
        xyz="-6.76297786869617E-09 0.027055001238608 -2.75401897969763E-05"
        rpy="0 0 0" />
      <mass
        value="0.0495277420594302" />
      <inertia
        ixx="1.41497431902944E-05"
        ixy="-5.54975854913089E-13"
        ixz="3.69455254005619E-12"
        iyy="9.94040203055089E-06"
        iyz="-1.8288699250526E-07"
        izz="1.2459726463517E-05" />
    </inertial>
    <visual>
      <origin
        xyz="0 0 0"
        rpy="0 0 0" />
      <geometry>
        <mesh
          filename="package://TestModule/meshes/base_link.STL" />
      </geometry>
      <material
        name="">
        <color
          rgba="0.792156862745098 0.819607843137255 0.933333333333333 1" />
      </material>
    </visual>
    <collision>
      <origin
        xyz="0 0 0"
        rpy="0 0 0" />
      <geometry>
        <mesh
          filename="package://TestModule/meshes/base_link.STL" />
      </geometry>
    </collision>
  </link>
  <link
    name="head">
    <inertial>
      <origin
        xyz="0.000524437183906545 -0.0129585093549575 0.000453299518954085"
        rpy="0 0 0" />
      <mass
        value="0.00301708508515438" />
      <inertia
        ixx="4.38014874293169E-07"
        ixy="4.25463023339811E-23"
        ixz="-1.06031804154792E-38"
        iyy="4.43521393164985E-07"
        iyz="9.48867566928348E-39"
        izz="4.38014874293169E-07" />
    </inertial>
    <visual>
      <origin
        xyz="0 0 0"
        rpy="0 0 0" />
      <geometry>
        <mesh
          filename="package://TestModule/meshes/head.STL" />
      </geometry>
      <material
        name="">
        <color
          rgba="0.792156862745098 0.819607843137255 0.933333333333333 1" />
      </material>
    </visual>
    <collision>
      <origin
        xyz="0 0 0"
        rpy="0 0 0" />
      <geometry>
        <mesh
          filename="package://TestModule/meshes/head.STL" />
      </geometry>
    </collision>
  </link>
  <joint
    name="base"
    type="fixed">
    <origin
      xyz="0 0 0"
      rpy="0 0 0" />
    <parent
      link="base_link" />
    <child
      link="head" />
    <axis
      xyz="0 0 0" />
  </joint>
  <link
    name="link1">
    <inertial>
      <origin
        xyz="0.0280266508378638 0.0506969680759188 -0.0215106904993166"
        rpy="0 0 0" />
      <mass
        value="0.0654174338681848" />
      <inertia
        ixx="2.24094591970622E-05"
        ixy="-2.69240795685015E-06"
        ixz="-6.8723065838877E-09"
        iyy="1.94647754174917E-05"
        iyz="-1.24130496939431E-08"
        izz="2.25049138700145E-05" />
    </inertial>
    <visual>
      <origin
        xyz="0 0 0"
        rpy="0 0 0" />
      <geometry>
        <mesh
          filename="package://TestModule/meshes/link1.STL" />
      </geometry>
      <material
        name="">
        <color
          rgba="0.792156862745098 0.819607843137255 0.933333333333333 1" />
      </material>
    </visual>
    <collision>
      <origin
        xyz="0 0 0"
        rpy="0 0 0" />
      <geometry>
        <mesh
          filename="package://TestModule/meshes/link1.STL" />
      </geometry>
    </collision>
  </link>
  <joint
    name="J1"
    type="continuous">
    <origin
      xyz="0 0.04109 0.0236000000000021"
      rpy="0 0 0" />
    <parent
      link="base_link" />
    <child
      link="link1" />
    <axis
      xyz="0 0 1" />
  </joint>
  <link
    name="link2">
    <inertial>
      <origin
        xyz="0.0579265123311286 0.000441593613520752 0.0215545523807336"
        rpy="0 0 0" />
      <mass
        value="0.0654174298247942" />
      <inertia
        ixx="1.78768428788828E-05"
        ixy="-2.27096808240911E-07"
        ixz="1.61661959297937E-08"
        iyy="2.39976170663151E-05"
        iyz="1.97069235553587E-08"
        izz="2.25046857009086E-05" />
    </inertial>
    <visual>
      <origin
        xyz="0 0 0"
        rpy="0 0 0" />
      <geometry>
        <mesh
          filename="package://TestModule/meshes/link2.STL" />
      </geometry>
      <material
        name="">
        <color
          rgba="0.792156862745098 0.819607843137255 0.933333333333333 1" />
      </material>
    </visual>
    <collision>
      <origin
        xyz="0 0 0"
        rpy="0 0 0" />
      <geometry>
        <mesh
          filename="package://TestModule/meshes/link2.STL" />
      </geometry>
    </collision>
  </link>
  <joint
    name="J2"
    type="continuous">
    <origin
      xyz="0.0239778311600057 0.0834079835079483 -0.0215000000000005"
      rpy="1.57079632679487 0 1.06542534387141" />
    <parent
      link="link1" />
    <child
      link="link2" />
    <axis
      xyz="0 0 1" />
  </joint>
  <link
    name="link3">
    <inertial>
      <origin
        xyz="-0.0123754985821023 0.0565779592489334 0.0215106899630436"
        rpy="0 0 0" />
      <mass
        value="0.0654174369601725" />
      <inertia
        ixx="2.36427864006503E-05"
        ixy="1.44782811177329E-06"
        ixz="-3.04186342654156E-09"
        iyy="1.82314489633984E-05"
        iyz="1.38586585553317E-08"
        izz="2.2504914605677E-05" />
    </inertial>
    <visual>
      <origin
        xyz="0 0 0"
        rpy="0 0 0" />
      <geometry>
        <mesh
          filename="package://TestModule/meshes/link3.STL" />
      </geometry>
      <material
        name="">
        <color
          rgba="0.792156862745098 0.819607843137255 0.933333333333333 1" />
      </material>
    </visual>
    <collision>
      <origin
        xyz="0 0 0"
        rpy="0 0 0" />
      <geometry>
        <mesh
          filename="package://TestModule/meshes/link3.STL" />
      </geometry>
    </collision>
  </link>
  <joint
    name="J3"
    type="continuous">
    <origin
      xyz="0.084431517435294 0.024267091432589 0.0212888668492358"
      rpy="-1.54686145887088 1.06525730615688 -3.1134294471901" />
    <parent
      link="link2" />
    <child
      link="link3" />
    <axis
      xyz="0 0 1" />
  </joint>
  <link
    name="link4">
    <inertial>
      <origin
        xyz="0.0556666216989015 0.0160295991494145 0.0213066206849623"
        rpy="0 0 0" />
      <mass
        value="0.0654174305884633" />
      <inertia
        ixx="1.84536923848352E-05"
        ixy="-1.80334125469087E-06"
        ixz="2.91606699825123E-08"
        iyy="2.34251550642555E-05"
        iyz="-8.33540521366826E-08"
        izz="2.25002990278056E-05" />
    </inertial>
    <visual>
      <origin
        xyz="0 0 0"
        rpy="0 0 0" />
      <geometry>
        <mesh
          filename="package://TestModule/meshes/link4.STL" />
      </geometry>
      <material
        name="">
        <color
          rgba="0.792156862745098 0.819607843137255 0.933333333333333 1" />
      </material>
    </visual>
    <collision>
      <origin
        xyz="0 0 0"
        rpy="0 0 0" />
      <geometry>
        <mesh
          filename="package://TestModule/meshes/link4.STL" />
      </geometry>
    </collision>
  </link>
  <joint
    name="J4"
    type="continuous">
    <origin
      xyz="0.000843497178304342 0.0867716927119091 0.0214999999999994"
      rpy="-1.57079632679492 -0.063593640842446 1.78664919794994" />
    <parent
      link="link3" />
    <child
      link="link4" />
    <axis
      xyz="0 0 1" />
  </joint>
  <link
    name="link5">
    <inertial>
      <origin
        xyz="-0.0226920572660301 -0.0532986524498286 0.0215106903634776"
        rpy="0 0 0" />
      <mass
        value="0.0654174406420127" />
      <inertia
        ixx="2.31935756558612E-05"
        ixy="-2.07972462215682E-06"
        ixz="-5.54972747822716E-09"
        iyy="1.86806621359453E-05"
        iyz="-1.30581487452523E-08"
        izz="2.25049157224695E-05" />
    </inertial>
    <visual>
      <origin
        xyz="0 0 0"
        rpy="0 0 0" />
      <geometry>
        <mesh
          filename="package://TestModule/meshes/link5.STL" />
      </geometry>
      <material
        name="">
        <color
          rgba="0.792156862745098 0.819607843137255 0.933333333333333 1" />
      </material>
    </visual>
    <collision>
      <origin
        xyz="0 0 0"
        rpy="0 0 0" />
      <geometry>
        <mesh
          filename="package://TestModule/meshes/link5.STL" />
      </geometry>
    </collision>
  </link>
  <joint
    name="J5"
    type="continuous">
    <origin
      xyz="0.0746665648716999 0.046085605146215 0.0224650961300724"
      rpy="1.81955028483087 -1.35692387492906 0.0407469615500211" />
    <parent
      link="link4" />
    <child
      link="link5" />
    <axis
      xyz="0 0 1" />
  </joint>
  <link
    name="link6">
    <inertial>
      <origin
        xyz="-0.0180491074912299 0.00437066108301949 0.021544034617132"
        rpy="0 0 0" />
      <mass
        value="0.0158896889808624" />
      <inertia
        ixx="8.13328192344153E-06"
        ixy="8.25101152313519E-07"
        ixz="-1.37905152531865E-08"
        iyy="1.13408230222265E-05"
        iyz="3.33942652627307E-09"
        izz="8.35517005485214E-06" />
    </inertial>
    <visual>
      <origin
        xyz="0 0 0"
        rpy="0 0 0" />
      <geometry>
        <mesh
          filename="package://TestModule/meshes/link6.STL" />
      </geometry>
      <material
        name="">
        <color
          rgba="0.792156862745098 0.819607843137255 0.933333333333333 1" />
      </material>
    </visual>
    <collision>
      <origin
        xyz="0 0 0"
        rpy="0 0 0" />
      <geometry>
        <mesh
          filename="package://TestModule/meshes/link6.STL" />
      </geometry>
    </collision>
  </link>
  <joint
    name="J6"
    type="continuous">
    <origin
      xyz="-0.0509605083676154 -0.0702485208877318 0.0215000000000055"
      rpy="1.57079632679492 -0.0230396782144055 1.16864809600552" />
    <parent
      link="link5" />
    <child
      link="link6" />
    <axis
      xyz="0 0 1" />
  </joint>
</robot>